Workbook

Sheet nutrition
A1: id | B1: calories | C1: proteins | D1: fat | E1: carbohydrate | F1: nama | G1: Kategori Kalori | H1: name
A2: 1 | B2: 280 | C2: 92 | D2: 284 | E2: 0 | F2: =PROPER(nutrition!$H2) -> Abon | G2: =IF(nutrition!$B2>300,"Tinggi Kalori",IF(nutrition!$B2>100,"Kalori Sedang","Rendah Kalori")) -> Kalori Sedang | H2: Abon
A3: 2 | B3: 513 | C3: 237 | D3: 37 | E3: 213 | F3: =PROPER(nutrition!$H3) -> Abon Haruwan | G3: =IF(nutrition!$B3>300,"Tinggi Kalori",IF(nutrition!$B3>100,"Kalori Sedang","Rendah Kalori")) -> Tinggi Kalori | H3: Abon haruwan
A4: 3 | B4: 0 | C4: 0 | D4: 2 | E4: 0 | F4: =PROPER(nutrition!$H4) -> Agar-Agar | G4: =IF(nutrition!$B4>300,"Tinggi Kalori",IF(nutrition!$B4>100,"Kalori Sedang","Rendah Kalori")) -> Rendah Kalori | H4: Agar-agar
A5: 4 | B5: 45 | C5: 11 | D5: 4 | E5: 108 | F5: =PROPER(nutrition!$H5) -> Akar Tonjong Segar | G5: =IF(nutrition!$B5>300,"Tinggi Kalori",IF(nutrition!$B5>100,"Kalori Sedang","Rendah Kalori")) -> Rendah Kalori | H5: Akar tonjong segar
A6: 5 | B6: 37 | C6: 44 | D6: 5 | E6: 38 | F6: =PROPER(nutrition!$H6) -> Aletoge Segar | G6: =IF(nutrition!$B6>300,"Tinggi Kalori",IF(nutrition!$B6>100,"Kalori Sedang","Rendah Kalori")) -> Rendah Kalori | H6: Aletoge segar
A7: 6 | B7: 85 | C7: 9 | D7: 65 | E7: 77 | F7: =PROPER(nutrition!$H7) -> Alpukat Segar | G7: =IF(nutrition!$B7>300,"Tinggi Kalori",IF(nutrition!$B7>100,"Kalori Sedang","Rendah Kalori")) -> Rendah Kalori | H7: Alpukat segar
A8: 7 | B8: 96 | C8: 37 | D8: 6 | E8: 191 | F8: =PROPER(nutrition!$H8) -> Ampas Kacang Hijau | G8: =IF(nutrition!$B8>300,"Tinggi Kalori",IF(nutrition!$B8>100,"Kalori Sedang","Rendah Kalori")) -> Rendah Kalori | H8: Ampas kacang hijau
A9: 8 | B9: 414 | C9: 266 | D9: 183 | E9: 413 | F9: =PROPER(nutrition!$H9) -> Ampas Tahu | G9: =IF(nutrition!$B9>300,"Tinggi Kalori",IF(nutrition!$B9>100,"Kalori Sedang","Rendah Kalori")) -> Tinggi Kalori | H9: Ampas Tahu
A10: 9 | B10: 75 | C10: 41 | D10: 21 | E10: 107 | F10: =PROPER(nutrition!$H10) -> Ampas Tahu Kukus | G10: =IF(nutrition!$B10>300,"Tinggi Kalori",IF(nutrition!$B10>100,"Kalori Sedang","Rendah Kalori")) -> Rendah Kalori | H10: Ampas tahu kukus
A11: 10 | B11: 67 | C11: 5 | D11: 21 | E11: 81 | F11: =PROPER(nutrition!$H11) -> Ampas Tahu Mentah | G11: =IF(nutrition!$B11>300,"Tinggi Kalori",IF(nutrition!$B11>100,"Kalori Sedang","Rendah Kalori")) -> Rendah Kalori | H11: Ampas tahu mentah
A12: 11 | B12: 184 | C12: 188 | D12: 14 | E12: 0 | F12: =PROPER(nutrition!$H12) -> Anak Sapi Daging Gemuk Segar | G12: =IF(nutrition!$B12>300,"Tinggi Kalori",IF(nutrition!$B12>100,"Kalori Sedang","Rendah Kalori")) -> Kalori Sedang | H12: Anak sapi daging gemuk segar
A13: 12 | B13: 174 | C13: 196 | D13: 10 | E13: 0 | F13: =PROPER(nutrition!$H13) -> Anak Sapi Daging Kurus Segar | G13: =IF(nutrition!$B13>300,"Tinggi Kalori",IF(nutrition!$B13>100,"Kalori Sedang","Rendah Kalori")) -> Kalori Sedang | H13: Anak sapi daging kurus segar
... A1347: 1346 | B1347: 52 | C1347: 33 | D1347: 25 | E1347: 4 | F1347: =PROPER(nutrition!$H1347) -> Yoghurt | G1347: =IF(nutrition!$B1347>300,"Tinggi Kalori",IF(nutrition!$B1347>100,"Kalori Sedang","Rendah Kalori")) -> Rendah Kalori | H1347: Yoghurt

Sheet Dashboard
B3: RINGKASAN STATISTIK | J3: carbohydrate | K3: 0
J5: Row Labels
B6: Rata-rata Kalori Keseluruhan | C6: =AVERAGE(nutrition!B:B) -> 238.65305 | J6: Abon
B7: Kandungan Protein Tertinggi | C7: =MAX(nutrition!C:C) -> 743 | E7: Mencari Nama Makanan dengan Protein Tertinggi | J7: Agar-agar
B8: Jumlah Makanan Kategori "Tinggi Kalori" | C8: =COUNTIF(nutrition!$G$2:$G$1347,"Tinggi Kalori") -> 412 | E8: =_xlfn.XLOOKUP(MAX(nutrition!C:C),nutrition!C:C,nutrition!H:H) -> Dendeng mujahir goreng | J8: Anak sapi daging gemuk segar
J9: Anak sapi daging kurus segar
J10: Anak sapi daging sedang segar
J11: Angsa
J12: Ayam
J13: Babat
J14: Babi daging gemuk segar
B15: Row Labels | C15: Max. of proteins | J15: Babi daging kurus segar
B16: Tepung Ikan | C16: 601 | J16: Bebek (itik)
B17: Ikan tepung mentah | C17: 601 | J17: Corned Beef
B18: Ikan sale lais mentah | C18: 613 | J18: Cue Selar Kuning
B19: Udang kering | C19: 624 | J19: Cumi-cumi goreng
B20: Udang kering mentah | C20: 626 | J20: Daging Anak Sapi
B21: Ikan Mujair dendeng mentah | C21: 683 | J21: Daging Asap
B22: Ikan Teri Kering tawar | C22: 687 | J22: Daging Babi Gemuk
B23: Ikan kayu kering | C23: 707 | J23: Daging Babi Kurus
B24: Ikan Mujair dendeng goreng | C24: 743 | J24: Daging Domba
B25: Dendeng mujahir goreng | C25: 743 | J25: Daging Kambing
B26: Grand Total | C26: 743 | J26: Daging Kerbau
J27: Daging Sapi
J28: Dendeng Daging Sapi
J29: Dideh darah sapi
J30: Domba daging gemuk segar
J31: Domba daging kurus segar
J32: Empal Goreng
J33: Ikan Asin bilis goreng
J34: Ikan Asin gabus goreng
J35: Ikan Asin japuh goreng
J36: Ikan Asin kering
B37: Row Labels | C37: Average of proteins | D37: Average of fat | E37: Average of carbohydrate | J37: Ikan Asin pari goreng
B38: Kalori Sedang | C38: 88.34968 | D38: 42.441365 | E38: 176.45416 | J38: Ikan Asin pepetek goreng
B39: Rendah Kalori | C39: 34.815054 | D39: 9.2 | E39: 72.546237 | J39: Ikan Asin sirinding goreng
B40: Tinggi Kalori | C40: 119.80825 | D40: 124.54369 | E40: 405.02184 | J40: Ikan Asin teri goreng
B41: Grand Total | C41: 79.484398 | D41: 56.08841 | E41: 210.52006 | J41: Ikan Bader (Tawes)
J42: Ikan Bandeng
J43: Ikan Bawal
...
